<robot name="robot_uro">
    <link name="base_link">
        <visual>
            <geometry>
                <box size="0.5 0.5 0.1"/>
            </geometry>
            <material name="blue"/>
        </visual>
    </link>

    <!-- Wheels -->
    <link name="left_wheel">
        <inertial>
            <mass value="0.5"/>
            <origin xyz="0 0 0" rpy="0 0 0"/>
            <inertia ixx="0.002" ixy="0.0" ixz="0.0" iyy="0.002" iyz="0.0" izz="0.001"/>
        </inertial>
        <collision>
            <geometry>
                <cylinder length="0.05" radius="0.1"/>
            </geometry>
        </collision>
        <visual>
            <geometry>
                <cylinder length="0.05" radius="0.1"/>
            </geometry>
            <material name="black"/>
        </visual>
    </link>

    <link name="right_wheel">
        <inertial>
            <mass value="0.5"/>
            <origin xyz="0 0 0" rpy="0 0 0"/>
            <inertia ixx="0.002" ixy="0.0" ixz="0.0" iyy="0.002" iyz="0.0" izz="0.001"/>
        </inertial>
        <collision>
            <geometry>
                <cylinder length="0.05" radius="0.1"/>
            </geometry>
        </collision>
        <visual>
            <geometry>
                <cylinder length="0.05" radius="0.1"/>
            </geometry>
            <material name="black"/>
        </visual>
    </link>
    <joint name="left_wheel_joint" type="continuous">
        <parent link="base_link"/>
        <child link="left_wheel"/>
        <origin xyz="0 0.3 0" rpy="0 0 0"/>
    </joint>
    <joint name="right_wheel_joint" type="continuous">
        <parent link="base_link"/>
        <child link="right_wheel"/>
        <origin xyz="0 -0.3 0" rpy="0 0 0"/>
    </joint>

    <!-- Differential Drive Plugin -->
    <gazebo>
        <plugin name="diff_drive_controller" filename="libgazebo_ros_diff_drive.so">
            <ros>
                <namespace>/</namespace>
            </ros>
            <left_joint>left_wheel_joint</left_joint>
            <right_joint>right_wheel_joint</right_joint>
            <wheel_separation>0.6</wheel_separation>
            <wheel_radius>0.1</wheel_radius>
            <command_topic>/cmd_vel</command_topic>
            <odometry_topic>/odom</odometry_topic>
            <publish_tf>true</publish_tf>
        </plugin>
    </gazebo>
</robot>